{
    DataVersion: 3465,
    size: [5, 3, 5],
    data: [
        {pos: [0, 0, 0], state: "extendedae_plus:super_assembler_matrix_frame{formed:true,powered:true,shape:block}"},
        {pos: [1, 0, 0], state: "extendedae_plus:super_assembler_matrix_frame{formed:true,powered:true,shape:column_x}"},
        {pos: [2, 0, 0], state: "extendedae_plus:super_assembler_matrix_frame{formed:true,powered:true,shape:column_x}"},
        {pos: [3, 0, 0], state: "extendedae_plus:super_assembler_matrix_frame{formed:true,powered:true,shape:column_x}"},
        {pos: [4, 0, 0], state: "extendedae_plus:super_assembler_matrix_frame{formed:true,powered:true,shape:block}"},
        {pos: [0, 0, 1], state: "extendedae_plus:super_assembler_matrix_frame{formed:true,powered:true,shape:column_z}"},
        {pos: [1, 0, 1], state: "extendedae:assembler_matrix_glass"},
        {pos: [2, 0, 1], state: "extendedae:assembler_matrix_glass"},
        {pos: [3, 0, 1], state: "extendedae:assembler_matrix_glass"},
        {pos: [4, 0, 1], state: "extendedae_plus:super_assembler_matrix_frame{formed:true,powered:true,shape:column_z}"},
        {pos: [0, 0, 2], state: "extendedae_plus:super_assembler_matrix_frame{formed:true,powered:true,shape:column_z}"},
        {pos: [1, 0, 2], state: "extendedae:assembler_matrix_glass"},
        {pos: [2, 0, 2], state: "extendedae:assembler_matrix_glass"},
        {pos: [3, 0, 2], state: "extendedae:assembler_matrix_glass"},
        {pos: [4, 0, 2], state: "extendedae_plus:super_assembler_matrix_frame{formed:true,powered:true,shape:column_z}"},
        {pos: [0, 0, 3], state: "extendedae_plus:super_assembler_matrix_frame{formed:true,powered:true,shape:column_z}"},
        {pos: [1, 0, 3], state: "extendedae:assembler_matrix_glass"},
        {pos: [2, 0, 3], state: "extendedae:assembler_matrix_glass"},
        {pos: [3, 0, 3], state: "extendedae:assembler_matrix_glass"},
        {pos: [4, 0, 3], state: "extendedae_plus:super_assembler_matrix_frame{formed:true,powered:true,shape:column_z}"},
        {pos: [0, 0, 4], state: "extendedae_plus:super_assembler_matrix_frame{formed:true,powered:true,shape:block}"},
        {pos: [1, 0, 4], state: "extendedae_plus:super_assembler_matrix_frame{formed:true,powered:true,shape:column_x}"},
        {pos: [2, 0, 4], state: "extendedae_plus:super_assembler_matrix_frame{formed:true,powered:true,shape:column_x}"},
        {pos: [3, 0, 4], state: "extendedae_plus:super_assembler_matrix_frame{formed:true,powered:true,shape:column_x}"},
        {pos: [4, 0, 4], state: "extendedae_plus:super_assembler_matrix_frame{formed:true,powered:true,shape:block}"},

        {pos: [0, 1, 0], state: "extendedae_plus:super_assembler_matrix_frame{formed:true,powered:true,shape:column_y}"},
        {pos: [0, 1, 1], state: "extendedae:assembler_matrix_glass"},
        {pos: [0, 1, 2], state: "extendedae:assembler_matrix_glass"},
        {pos: [0, 1, 3], state: "extendedae:assembler_matrix_glass"},
        {pos: [0, 1, 4], state: "extendedae_plus:super_assembler_matrix_frame{formed:true,powered:true,shape:column_y}"},
        {pos: [1, 1, 0], state: "extendedae:assembler_matrix_glass"},
        {pos: [1, 1, 1], state: "extendedae_plus:assembler_matrix_hybrid_plus{formed:true,powered:true}"},
        {pos: [1, 1, 2], state: "extendedae_plus:assembler_matrix_hybrid_plus{formed:true,powered:true}"},
        {pos: [1, 1, 3], state: "extendedae_plus:assembler_matrix_hybrid_plus{formed:true,powered:true}"},
        {pos: [1, 1, 4], state: "extendedae:assembler_matrix_glass"},
        {pos: [2, 1, 0], state: "extendedae:assembler_matrix_glass"},
        {pos: [2, 1, 1], state: "extendedae_plus:assembler_matrix_hybrid_plus{formed:true,powered:true}"},
        {pos: [2, 1, 2], state: "extendedae_plus:assembler_matrix_hybrid_plus{formed:true,powered:true}"},
        {pos: [2, 1, 3], state: "extendedae_plus:assembler_matrix_hybrid_plus{formed:true,powered:true}"},
        {pos: [2, 1, 4], state: "extendedae:assembler_matrix_glass"},
        {pos: [3, 1, 0], state: "extendedae:assembler_matrix_glass"},
        {pos: [3, 1, 1], state: "extendedae_plus:assembler_matrix_hybrid_plus{formed:true,powered:true}"},
        {pos: [3, 1, 2], state: "extendedae_plus:assembler_matrix_hybrid_plus{formed:true,powered:true}"},
        {pos: [3, 1, 3], state: "extendedae_plus:assembler_matrix_hybrid_plus{formed:true,powered:true}"},
        {pos: [3, 1, 4], state: "extendedae:assembler_matrix_glass"},
        {pos: [4, 1, 0], state: "extendedae_plus:super_assembler_matrix_frame{formed:true,powered:true,shape:column_y}"},
        {pos: [4, 1, 1], state: "extendedae:assembler_matrix_glass"},
        {pos: [4, 1, 2], state: "extendedae:assembler_matrix_glass"},
        {pos: [4, 1, 3], state: "extendedae:assembler_matrix_glass"},
        {pos: [4, 1, 4], state: "extendedae_plus:super_assembler_matrix_frame{formed:true,powered:true,shape:column_y}"},

        {pos: [0, 2, 0], state: "extendedae_plus:super_assembler_matrix_frame{formed:true,powered:true,shape:block}"},
        {pos: [1, 2, 0], state: "extendedae_plus:super_assembler_matrix_frame{formed:true,powered:true,shape:column_x}"},
        {pos: [2, 2, 0], state: "extendedae_plus:super_assembler_matrix_frame{formed:true,powered:true,shape:column_x}"},
        {pos: [3, 2, 0], state: "extendedae_plus:super_assembler_matrix_frame{formed:true,powered:true,shape:column_x}"},
        {pos: [4, 2, 0], state: "extendedae_plus:super_assembler_matrix_frame{formed:true,powered:true,shape:block}"},
        {pos: [0, 2, 1], state: "extendedae_plus:super_assembler_matrix_frame{formed:true,powered:true,shape:column_z}"},
        {pos: [1, 2, 1], state: "extendedae:assembler_matrix_glass"},
        {pos: [2, 2, 1], state: "extendedae:assembler_matrix_glass"},
        {pos: [3, 2, 1], state: "extendedae:assembler_matrix_glass"},
        {pos: [4, 2, 1], state: "extendedae_plus:super_assembler_matrix_frame{formed:true,powered:true,shape:column_z}"},
        {pos: [0, 2, 2], state: "extendedae_plus:super_assembler_matrix_frame{formed:true,powered:true,shape:column_z}"},
        {pos: [1, 2, 2], state: "extendedae:assembler_matrix_glass"},
        {pos: [2, 2, 2], state: "extendedae:assembler_matrix_glass"},
        {pos: [3, 2, 2], state: "extendedae:assembler_matrix_glass"},
        {pos: [4, 2, 2], state: "extendedae_plus:super_assembler_matrix_frame{formed:true,powered:true,shape:column_z}"},
        {pos: [0, 2, 3], state: "extendedae_plus:super_assembler_matrix_frame{formed:true,powered:true,shape:column_z}"},
        {pos: [1, 2, 3], state: "extendedae:assembler_matrix_glass"},
        {pos: [2, 2, 3], state: "extendedae:assembler_matrix_glass"},
        {pos: [3, 2, 3], state: "extendedae:assembler_matrix_glass"},
        {pos: [4, 2, 3], state: "extendedae_plus:super_assembler_matrix_frame{formed:true,powered:true,shape:column_z}"},
        {pos: [0, 2, 4], state: "extendedae_plus:super_assembler_matrix_frame{formed:true,powered:true,shape:block}"},
        {pos: [1, 2, 4], state: "extendedae_plus:super_assembler_matrix_frame{formed:true,powered:true,shape:column_x}"},
        {pos: [2, 2, 4], state: "extendedae_plus:super_assembler_matrix_frame{formed:true,powered:true,shape:column_x}"},
        {pos: [3, 2, 4], state: "extendedae_plus:super_assembler_matrix_frame{formed:true,powered:true,shape:column_x}"},
        {pos: [4, 2, 4], state: "extendedae_plus:super_assembler_matrix_frame{formed:true,powered:true,shape:block}"}
    ],
    entities: [],
    palette: [
        "extendedae_plus:super_assembler_matrix_frame{formed:true,powered:true,shape:block}",
        "extendedae_plus:super_assembler_matrix_frame{formed:true,powered:true,shape:column_x}",
        "extendedae_plus:super_assembler_matrix_frame{formed:true,powered:true,shape:column_y}",
        "extendedae_plus:super_assembler_matrix_frame{formed:true,powered:true,shape:column_z}",
        "extendedae:assembler_matrix_glass",
        "extendedae_plus:assembler_matrix_hybrid_plus{formed:true,powered:true}"
    ]
}
